[ERROR][2018-05-25 08:50:11,667][org.springframework.scheduling.support.TaskUtils$LoggingErrorHandler]Unexpected error occurred in scheduled task.
java.lang.RuntimeException: get connection error!
	at com.hl95.utils.JdbcUtil.getConnection(JdbcUtil.java:61)
	at com.hl95.common.controller.SmsManageController.propelSms(SmsManageController.java:79)
	at sun.reflect.NativeMethodAccessorImpl.invoke0(Native Method)
	at sun.reflect.NativeMethodAccessorImpl.invoke(NativeMethodAccessorImpl.java:62)
	at sun.reflect.DelegatingMethodAccessorImpl.invoke(DelegatingMethodAccessorImpl.java:43)
	at java.lang.reflect.Method.invoke(Method.java:498)
	at org.springframework.scheduling.support.ScheduledMethodRunnable.run(ScheduledMethodRunnable.java:65)
	at org.springframework.scheduling.support.DelegatingErrorHandlingRunnable.run(DelegatingErrorHandlingRunnable.java:54)
	at java.util.concurrent.Executors$RunnableAdapter.call(Executors.java:511)
	at java.util.concurrent.FutureTask.runAndReset(FutureTask.java:308)
	at java.util.concurrent.ScheduledThreadPoolExecutor$ScheduledFutureTask.access$301(ScheduledThreadPoolExecutor.java:180)
	at java.util.concurrent.ScheduledThreadPoolExecutor$ScheduledFutureTask.run(ScheduledThreadPoolExecutor.java:294)
	at java.util.concurrent.ThreadPoolExecutor.runWorker(ThreadPoolExecutor.java:1149)
	at java.util.concurrent.ThreadPoolExecutor$Worker.run(ThreadPoolExecutor.java:624)
	at java.lang.Thread.run(Thread.java:748)
Caused by: com.mysql.jdbc.exceptions.jdbc4.MySQLSyntaxErrorException: Access denied for user 'hljw'@'%' to database 'hl_jw'
	at sun.reflect.NativeConstructorAccessorImpl.newInstance0(Native Method)
	at sun.reflect.NativeConstructorAccessorImpl.newInstance(NativeConstructorAccessorImpl.java:62)
	at sun.reflect.DelegatingConstructorAccessorImpl.newInstance(DelegatingConstructorAccessorImpl.java:45)
	at java.lang.reflect.Constructor.newInstance(Constructor.java:423)
	at com.mysql.jdbc.Util.handleNewInstance(Util.java:377)
	at com.mysql.jdbc.Util.getInstance(Util.java:360)
	at com.mysql.jdbc.SQLError.createSQLException(SQLError.java:978)
	at com.mysql.jdbc.MysqlIO.checkErrorPacket(MysqlIO.java:3887)
	at com.mysql.jdbc.MysqlIO.checkErrorPacket(MysqlIO.java:3823)
	at com.mysql.jdbc.MysqlIO.checkErrorPacket(MysqlIO.java:870)
	at com.mysql.jdbc.MysqlIO.proceedHandshakeWithPluggableAuthentication(MysqlIO.java:1659)
	at com.mysql.jdbc.MysqlIO.doHandshake(MysqlIO.java:1206)
	at com.mysql.jdbc.ConnectionImpl.coreConnect(ConnectionImpl.java:2234)
	at com.mysql.jdbc.ConnectionImpl.connectOneTryOnly(ConnectionImpl.java:2265)
	at com.mysql.jdbc.ConnectionImpl.createNewIO(ConnectionImpl.java:2064)
	at com.mysql.jdbc.ConnectionImpl.<init>(ConnectionImpl.java:790)
	at com.mysql.jdbc.JDBC4Connection.<init>(JDBC4Connection.java:44)
	at sun.reflect.NativeConstructorAccessorImpl.newInstance0(Native Method)
	at sun.reflect.NativeConstructorAccessorImpl.newInstance(NativeConstructorAccessorImpl.java:62)
	at sun.reflect.DelegatingConstructorAccessorImpl.newInstance(DelegatingConstructorAccessorImpl.java:45)
	at java.lang.reflect.Constructor.newInstance(Constructor.java:423)
	at com.mysql.jdbc.Util.handleNewInstance(Util.java:377)
	at com.mysql.jdbc.ConnectionImpl.getInstance(ConnectionImpl.java:395)
	at com.mysql.jdbc.NonRegisteringDriver.connect(NonRegisteringDriver.java:325)
	at java.sql.DriverManager.getConnection(DriverManager.java:664)
	at java.sql.DriverManager.getConnection(DriverManager.java:247)
	at com.hl95.utils.JdbcUtil.getConnection(JdbcUtil.java:59)
	... 14 more
[ERROR][2018-05-25 08:50:11,932][org.springframework.scheduling.support.TaskUtils$LoggingErrorHandler]Unexpected error occurred in scheduled task.
java.lang.RuntimeException: get connection error!
	at com.hl95.utils.JdbcUtil.getConnection(JdbcUtil.java:61)
	at com.hl95.common.controller.SmsManageController.propelSms(SmsManageController.java:79)
	at sun.reflect.NativeMethodAccessorImpl.invoke0(Native Method)
	at sun.reflect.NativeMethodAccessorImpl.invoke(NativeMethodAccessorImpl.java:62)
	at sun.reflect.DelegatingMethodAccessorImpl.invoke(DelegatingMethodAccessorImpl.java:43)
	at java.lang.reflect.Method.invoke(Method.java:498)
	at org.springframework.scheduling.support.ScheduledMethodRunnable.run(ScheduledMethodRunnable.java:65)
	at org.springframework.scheduling.support.DelegatingErrorHandlingRunnable.run(DelegatingErrorHandlingRunnable.java:54)
	at java.util.concurrent.Executors$RunnableAdapter.call(Executors.java:511)
	at java.util.concurrent.FutureTask.runAndReset(FutureTask.java:308)
	at java.util.concurrent.ScheduledThreadPoolExecutor$ScheduledFutureTask.access$301(ScheduledThreadPoolExecutor.java:180)
	at java.util.concurrent.ScheduledThreadPoolExecutor$ScheduledFutureTask.run(ScheduledThreadPoolExecutor.java:294)
	at java.util.concurrent.ThreadPoolExecutor.runWorker(ThreadPoolExecutor.java:1149)
	at java.util.concurrent.ThreadPoolExecutor$Worker.run(ThreadPoolExecutor.java:624)
	at java.lang.Thread.run(Thread.java:748)
Caused by: com.mysql.jdbc.exceptions.jdbc4.MySQLSyntaxErrorException: Access denied for user 'hljw'@'%' to database 'hl_jw'
	at sun.reflect.NativeConstructorAccessorImpl.newInstance0(Native Method)
	at sun.reflect.NativeConstructorAccessorImpl.newInstance(NativeConstructorAccessorImpl.java:62)
	at sun.reflect.DelegatingConstructorAccessorImpl.newInstance(DelegatingConstructorAccessorImpl.java:45)
	at java.lang.reflect.Constructor.newInstance(Constructor.java:423)
	at com.mysql.jdbc.Util.handleNewInstance(Util.java:377)
	at com.mysql.jdbc.Util.getInstance(Util.java:360)
	at com.mysql.jdbc.SQLError.createSQLException(SQLError.java:978)
	at com.mysql.jdbc.MysqlIO.checkErrorPacket(MysqlIO.java:3887)
	at com.mysql.jdbc.MysqlIO.checkErrorPacket(MysqlIO.java:3823)
	at com.mysql.jdbc.MysqlIO.checkErrorPacket(MysqlIO.java:870)
	at com.mysql.jdbc.MysqlIO.proceedHandshakeWithPluggableAuthentication(MysqlIO.java:1659)
	at com.mysql.jdbc.MysqlIO.doHandshake(MysqlIO.java:1206)
	at com.mysql.jdbc.ConnectionImpl.coreConnect(ConnectionImpl.java:2234)
	at com.mysql.jdbc.ConnectionImpl.connectOneTryOnly(ConnectionImpl.java:2265)
	at com.mysql.jdbc.ConnectionImpl.createNewIO(ConnectionImpl.java:2064)
	at com.mysql.jdbc.ConnectionImpl.<init>(ConnectionImpl.java:790)
	at com.mysql.jdbc.JDBC4Connection.<init>(JDBC4Connection.java:44)
	at sun.reflect.NativeConstructorAccessorImpl.newInstance0(Native Method)
	at sun.reflect.NativeConstructorAccessorImpl.newInstance(NativeConstructorAccessorImpl.java:62)
	at sun.reflect.DelegatingConstructorAccessorImpl.newInstance(DelegatingConstructorAccessorImpl.java:45)
	at java.lang.reflect.Constructor.newInstance(Constructor.java:423)
	at com.mysql.jdbc.Util.handleNewInstance(Util.java:377)
	at com.mysql.jdbc.ConnectionImpl.getInstance(ConnectionImpl.java:395)
	at com.mysql.jdbc.NonRegisteringDriver.connect(NonRegisteringDriver.java:325)
	at java.sql.DriverManager.getConnection(DriverManager.java:664)
	at java.sql.DriverManager.getConnection(DriverManager.java:247)
	at com.hl95.utils.JdbcUtil.getConnection(JdbcUtil.java:59)
	... 14 more
[ERROR][2018-05-25 08:50:12,938][org.springframework.scheduling.support.TaskUtils$LoggingErrorHandler]Unexpected error occurred in scheduled task.
java.lang.RuntimeException: get connection error!
	at com.hl95.utils.JdbcUtil.getConnection(JdbcUtil.java:61)
	at com.hl95.common.controller.SmsManageController.propelSms(SmsManageController.java:79)
	at sun.reflect.NativeMethodAccessorImpl.invoke0(Native Method)
	at sun.reflect.NativeMethodAccessorImpl.invoke(NativeMethodAccessorImpl.java:62)
	at sun.reflect.DelegatingMethodAccessorImpl.invoke(DelegatingMethodAccessorImpl.java:43)
	at java.lang.reflect.Method.invoke(Method.java:498)
	at org.springframework.scheduling.support.ScheduledMethodRunnable.run(ScheduledMethodRunnable.java:65)
	at org.springframework.scheduling.support.DelegatingErrorHandlingRunnable.run(DelegatingErrorHandlingRunnable.java:54)
	at java.util.concurrent.Executors$RunnableAdapter.call(Executors.java:511)
	at java.util.concurrent.FutureTask.runAndReset(FutureTask.java:308)
	at java.util.concurrent.ScheduledThreadPoolExecutor$ScheduledFutureTask.access$301(ScheduledThreadPoolExecutor.java:180)
	at java.util.concurrent.ScheduledThreadPoolExecutor$ScheduledFutureTask.run(ScheduledThreadPoolExecutor.java:294)
	at java.util.concurrent.ThreadPoolExecutor.runWorker(ThreadPoolExecutor.java:1149)
	at java.util.concurrent.ThreadPoolExecutor$Worker.run(ThreadPoolExecutor.java:624)
	at java.lang.Thread.run(Thread.java:748)
Caused by: com.mysql.jdbc.exceptions.jdbc4.MySQLSyntaxErrorException: Access denied for user 'hljw'@'%' to database 'hl_jw'
	at sun.reflect.NativeConstructorAccessorImpl.newInstance0(Native Method)
	at sun.reflect.NativeConstructorAccessorImpl.newInstance(NativeConstructorAccessorImpl.java:62)
	at sun.reflect.DelegatingConstructorAccessorImpl.newInstance(DelegatingConstructorAccessorImpl.java:45)
	at java.lang.reflect.Constructor.newInstance(Constructor.java:423)
	at com.mysql.jdbc.Util.handleNewInstance(Util.java:377)
	at com.mysql.jdbc.Util.getInstance(Util.java:360)
	at com.mysql.jdbc.SQLError.createSQLException(SQLError.java:978)
	at com.mysql.jdbc.MysqlIO.checkErrorPacket(MysqlIO.java:3887)
	at com.mysql.jdbc.MysqlIO.checkErrorPacket(MysqlIO.java:3823)
	at com.mysql.jdbc.MysqlIO.checkErrorPacket(MysqlIO.java:870)
	at com.mysql.jdbc.MysqlIO.proceedHandshakeWithPluggableAuthentication(MysqlIO.java:1659)
	at com.mysql.jdbc.MysqlIO.doHandshake(MysqlIO.java:1206)
	at com.mysql.jdbc.ConnectionImpl.coreConnect(ConnectionImpl.java:2234)
	at com.mysql.jdbc.ConnectionImpl.connectOneTryOnly(ConnectionImpl.java:2265)
	at com.mysql.jdbc.ConnectionImpl.createNewIO(ConnectionImpl.java:2064)
	at com.mysql.jdbc.ConnectionImpl.<init>(ConnectionImpl.java:790)
	at com.mysql.jdbc.JDBC4Connection.<init>(JDBC4Connection.java:44)
	at sun.reflect.NativeConstructorAccessorImpl.newInstance0(Native Method)
	at sun.reflect.NativeConstructorAccessorImpl.newInstance(NativeConstructorAccessorImpl.java:62)
	at sun.reflect.DelegatingConstructorAccessorImpl.newInstance(DelegatingConstructorAccessorImpl.java:45)
	at java.lang.reflect.Constructor.newInstance(Constructor.java:423)
	at com.mysql.jdbc.Util.handleNewInstance(Util.java:377)
	at com.mysql.jdbc.ConnectionImpl.getInstance(ConnectionImpl.java:395)
	at com.mysql.jdbc.NonRegisteringDriver.connect(NonRegisteringDriver.java:325)
	at java.sql.DriverManager.getConnection(DriverManager.java:664)
	at java.sql.DriverManager.getConnection(DriverManager.java:247)
	at com.hl95.utils.JdbcUtil.getConnection(JdbcUtil.java:59)
	... 14 more
[ERROR][2018-05-25 08:50:13,933][org.springframework.scheduling.support.TaskUtils$LoggingErrorHandler]Unexpected error occurred in scheduled task.
java.lang.RuntimeException: get connection error!
	at com.hl95.utils.JdbcUtil.getConnection(JdbcUtil.java:61)
	at com.hl95.common.controller.SmsManageController.propelSms(SmsManageController.java:79)
	at sun.reflect.NativeMethodAccessorImpl.invoke0(Native Method)
	at sun.reflect.NativeMethodAccessorImpl.invoke(NativeMethodAccessorImpl.java:62)
	at sun.reflect.DelegatingMethodAccessorImpl.invoke(DelegatingMethodAccessorImpl.java:43)
	at java.lang.reflect.Method.invoke(Method.java:498)
	at org.springframework.scheduling.support.ScheduledMethodRunnable.run(ScheduledMethodRunnable.java:65)
	at org.springframework.scheduling.support.DelegatingErrorHandlingRunnable.run(DelegatingErrorHandlingRunnable.java:54)
	at java.util.concurrent.Executors$RunnableAdapter.call(Executors.java:511)
	at java.util.concurrent.FutureTask.runAndReset(FutureTask.java:308)
	at java.util.concurrent.ScheduledThreadPoolExecutor$ScheduledFutureTask.access$301(ScheduledThreadPoolExecutor.java:180)
	at java.util.concurrent.ScheduledThreadPoolExecutor$ScheduledFutureTask.run(ScheduledThreadPoolExecutor.java:294)
	at java.util.concurrent.ThreadPoolExecutor.runWorker(ThreadPoolExecutor.java:1149)
	at java.util.concurrent.ThreadPoolExecutor$Worker.run(ThreadPoolExecutor.java:624)
	at java.lang.Thread.run(Thread.java:748)
Caused by: com.mysql.jdbc.exceptions.jdbc4.MySQLSyntaxErrorException: Access denied for user 'hljw'@'%' to database 'hl_jw'
	at sun.reflect.NativeConstructorAccessorImpl.newInstance0(Native Method)
	at sun.reflect.NativeConstructorAccessorImpl.newInstance(NativeConstructorAccessorImpl.java:62)
	at sun.reflect.DelegatingConstructorAccessorImpl.newInstance(DelegatingConstructorAccessorImpl.java:45)
	at java.lang.reflect.Constructor.newInstance(Constructor.java:423)
	at com.mysql.jdbc.Util.handleNewInstance(Util.java:377)
	at com.mysql.jdbc.Util.getInstance(Util.java:360)
	at com.mysql.jdbc.SQLError.createSQLException(SQLError.java:978)
	at com.mysql.jdbc.MysqlIO.checkErrorPacket(MysqlIO.java:3887)
	at com.mysql.jdbc.MysqlIO.checkErrorPacket(MysqlIO.java:3823)
	at com.mysql.jdbc.MysqlIO.checkErrorPacket(MysqlIO.java:870)
	at com.mysql.jdbc.MysqlIO.proceedHandshakeWithPluggableAuthentication(MysqlIO.java:1659)
	at com.mysql.jdbc.MysqlIO.doHandshake(MysqlIO.java:1206)
	at com.mysql.jdbc.ConnectionImpl.coreConnect(ConnectionImpl.java:2234)
	at com.mysql.jdbc.ConnectionImpl.connectOneTryOnly(ConnectionImpl.java:2265)
	at com.mysql.jdbc.ConnectionImpl.createNewIO(ConnectionImpl.java:2064)
	at com.mysql.jdbc.ConnectionImpl.<init>(ConnectionImpl.java:790)
	at com.mysql.jdbc.JDBC4Connection.<init>(JDBC4Connection.java:44)
	at sun.reflect.NativeConstructorAccessorImpl.newInstance0(Native Method)
	at sun.reflect.NativeConstructorAccessorImpl.newInstance(NativeConstructorAccessorImpl.java:62)
	at sun.reflect.DelegatingConstructorAccessorImpl.newInstance(DelegatingConstructorAccessorImpl.java:45)
	at java.lang.reflect.Constructor.newInstance(Constructor.java:423)
	at com.mysql.jdbc.Util.handleNewInstance(Util.java:377)
	at com.mysql.jdbc.ConnectionImpl.getInstance(ConnectionImpl.java:395)
	at com.mysql.jdbc.NonRegisteringDriver.connect(NonRegisteringDriver.java:325)
	at java.sql.DriverManager.getConnection(DriverManager.java:664)
	at java.sql.DriverManager.getConnection(DriverManager.java:247)
	at com.hl95.utils.JdbcUtil.getConnection(JdbcUtil.java:59)
	... 14 more
[ERROR][2018-05-25 08:50:14,935][org.springframework.scheduling.support.TaskUtils$LoggingErrorHandler]Unexpected error occurred in scheduled task.
java.lang.RuntimeException: get connection error!
	at com.hl95.utils.JdbcUtil.getConnection(JdbcUtil.java:61)
	at com.hl95.common.controller.SmsManageController.propelSms(SmsManageController.java:79)
	at sun.reflect.NativeMethodAccessorImpl.invoke0(Native Method)
	at sun.reflect.NativeMethodAccessorImpl.invoke(NativeMethodAccessorImpl.java:62)
	at sun.reflect.DelegatingMethodAccessorImpl.invoke(DelegatingMethodAccessorImpl.java:43)
	at java.lang.reflect.Method.invoke(Method.java:498)
	at org.springframework.scheduling.support.ScheduledMethodRunnable.run(ScheduledMethodRunnable.java:65)
	at org.springframework.scheduling.support.DelegatingErrorHandlingRunnable.run(DelegatingErrorHandlingRunnable.java:54)
	at java.util.concurrent.Executors$RunnableAdapter.call(Executors.java:511)
	at java.util.concurrent.FutureTask.runAndReset(FutureTask.java:308)
	at java.util.concurrent.ScheduledThreadPoolExecutor$ScheduledFutureTask.access$301(ScheduledThreadPoolExecutor.java:180)
	at java.util.concurrent.ScheduledThreadPoolExecutor$ScheduledFutureTask.run(ScheduledThreadPoolExecutor.java:294)
	at java.util.concurrent.ThreadPoolExecutor.runWorker(ThreadPoolExecutor.java:1149)
	at java.util.concurrent.ThreadPoolExecutor$Worker.run(ThreadPoolExecutor.java:624)
	at java.lang.Thread.run(Thread.java:748)
Caused by: com.mysql.jdbc.exceptions.jdbc4.MySQLSyntaxErrorException: Access denied for user 'hljw'@'%' to database 'hl_jw'
	at sun.reflect.NativeConstructorAccessorImpl.newInstance0(Native Method)
	at sun.reflect.NativeConstructorAccessorImpl.newInstance(NativeConstructorAccessorImpl.java:62)
	at sun.reflect.DelegatingConstructorAccessorImpl.newInstance(DelegatingConstructorAccessorImpl.java:45)
	at java.lang.reflect.Constructor.newInstance(Constructor.java:423)
	at com.mysql.jdbc.Util.handleNewInstance(Util.java:377)
	at com.mysql.jdbc.Util.getInstance(Util.java:360)
	at com.mysql.jdbc.SQLError.createSQLException(SQLError.java:978)
	at com.mysql.jdbc.MysqlIO.checkErrorPacket(MysqlIO.java:3887)
	at com.mysql.jdbc.MysqlIO.checkErrorPacket(MysqlIO.java:3823)
	at com.mysql.jdbc.MysqlIO.checkErrorPacket(MysqlIO.java:870)
	at com.mysql.jdbc.MysqlIO.proceedHandshakeWithPluggableAuthentication(MysqlIO.java:1659)
	at com.mysql.jdbc.MysqlIO.doHandshake(MysqlIO.java:1206)
	at com.mysql.jdbc.ConnectionImpl.coreConnect(ConnectionImpl.java:2234)
	at com.mysql.jdbc.ConnectionImpl.connectOneTryOnly(ConnectionImpl.java:2265)
	at com.mysql.jdbc.ConnectionImpl.createNewIO(ConnectionImpl.java:2064)
	at com.mysql.jdbc.ConnectionImpl.<init>(ConnectionImpl.java:790)
	at com.mysql.jdbc.JDBC4Connection.<init>(JDBC4Connection.java:44)
	at sun.reflect.NativeConstructorAccessorImpl.newInstance0(Native Method)
	at sun.reflect.NativeConstructorAccessorImpl.newInstance(NativeConstructorAccessorImpl.java:62)
	at sun.reflect.DelegatingConstructorAccessorImpl.newInstance(DelegatingConstructorAccessorImpl.java:45)
	at java.lang.reflect.Constructor.newInstance(Constructor.java:423)
	at com.mysql.jdbc.Util.handleNewInstance(Util.java:377)
	at com.mysql.jdbc.ConnectionImpl.getInstance(ConnectionImpl.java:395)
	at com.mysql.jdbc.NonRegisteringDriver.connect(NonRegisteringDriver.java:325)
	at java.sql.DriverManager.getConnection(DriverManager.java:664)
	at java.sql.DriverManager.getConnection(DriverManager.java:247)
	at com.hl95.utils.JdbcUtil.getConnection(JdbcUtil.java:59)
	... 14 more
[ERROR][2018-05-25 08:50:15,935][org.springframework.scheduling.support.TaskUtils$LoggingErrorHandler]Unexpected error occurred in scheduled task.
java.lang.RuntimeException: get connection error!
	at com.hl95.utils.JdbcUtil.getConnection(JdbcUtil.java:61)
	at com.hl95.common.controller.SmsManageController.propelSms(SmsManageController.java:79)
	at sun.reflect.NativeMethodAccessorImpl.invoke0(Native Method)
	at sun.reflect.NativeMethodAccessorImpl.invoke(NativeMethodAccessorImpl.java:62)
	at sun.reflect.DelegatingMethodAccessorImpl.invoke(DelegatingMethodAccessorImpl.java:43)
	at java.lang.reflect.Method.invoke(Method.java:498)
	at org.springframework.scheduling.support.ScheduledMethodRunnable.run(ScheduledMethodRunnable.java:65)
	at org.springframework.scheduling.support.DelegatingErrorHandlingRunnable.run(DelegatingErrorHandlingRunnable.java:54)
	at java.util.concurrent.Executors$RunnableAdapter.call(Executors.java:511)
	at java.util.concurrent.FutureTask.runAndReset(FutureTask.java:308)
	at java.util.concurrent.ScheduledThreadPoolExecutor$ScheduledFutureTask.access$301(ScheduledThreadPoolExecutor.java:180)
	at java.util.concurrent.ScheduledThreadPoolExecutor$ScheduledFutureTask.run(ScheduledThreadPoolExecutor.java:294)
	at java.util.concurrent.ThreadPoolExecutor.runWorker(ThreadPoolExecutor.java:1149)
	at java.util.concurrent.ThreadPoolExecutor$Worker.run(ThreadPoolExecutor.java:624)
	at java.lang.Thread.run(Thread.java:748)
Caused by: com.mysql.jdbc.exceptions.jdbc4.MySQLSyntaxErrorException: Access denied for user 'hljw'@'%' to database 'hl_jw'
	at sun.reflect.NativeConstructorAccessorImpl.newInstance0(Native Method)
	at sun.reflect.NativeConstructorAccessorImpl.newInstance(NativeConstructorAccessorImpl.java:62)
	at sun.reflect.DelegatingConstructorAccessorImpl.newInstance(DelegatingConstructorAccessorImpl.java:45)
	at java.lang.reflect.Constructor.newInstance(Constructor.java:423)
	at com.mysql.jdbc.Util.handleNewInstance(Util.java:377)
	at com.mysql.jdbc.Util.getInstance(Util.java:360)
	at com.mysql.jdbc.SQLError.createSQLException(SQLError.java:978)
	at com.mysql.jdbc.MysqlIO.checkErrorPacket(MysqlIO.java:3887)
	at com.mysql.jdbc.MysqlIO.checkErrorPacket(MysqlIO.java:3823)
	at com.mysql.jdbc.MysqlIO.checkErrorPacket(MysqlIO.java:870)
	at com.mysql.jdbc.MysqlIO.proceedHandshakeWithPluggableAuthentication(MysqlIO.java:1659)
	at com.mysql.jdbc.MysqlIO.doHandshake(MysqlIO.java:1206)
	at com.mysql.jdbc.ConnectionImpl.coreConnect(ConnectionImpl.java:2234)
	at com.mysql.jdbc.ConnectionImpl.connectOneTryOnly(ConnectionImpl.java:2265)
	at com.mysql.jdbc.ConnectionImpl.createNewIO(ConnectionImpl.java:2064)
	at com.mysql.jdbc.ConnectionImpl.<init>(ConnectionImpl.java:790)
	at com.mysql.jdbc.JDBC4Connection.<init>(JDBC4Connection.java:44)
	at sun.reflect.NativeConstructorAccessorImpl.newInstance0(Native Method)
	at sun.reflect.NativeConstructorAccessorImpl.newInstance(NativeConstructorAccessorImpl.java:62)
	at sun.reflect.DelegatingConstructorAccessorImpl.newInstance(DelegatingConstructorAccessorImpl.java:45)
	at java.lang.reflect.Constructor.newInstance(Constructor.java:423)
	at com.mysql.jdbc.Util.handleNewInstance(Util.java:377)
	at com.mysql.jdbc.ConnectionImpl.getInstance(ConnectionImpl.java:395)
	at com.mysql.jdbc.NonRegisteringDriver.connect(NonRegisteringDriver.java:325)
	at java.sql.DriverManager.getConnection(DriverManager.java:664)
	at java.sql.DriverManager.getConnection(DriverManager.java:247)
	at com.hl95.utils.JdbcUtil.getConnection(JdbcUtil.java:59)
	... 14 more
[ERROR][2018-05-25 08:50:16,938][org.springframework.scheduling.support.TaskUtils$LoggingErrorHandler]Unexpected error occurred in scheduled task.
java.lang.RuntimeException: get connection error!
	at com.hl95.utils.JdbcUtil.getConnection(JdbcUtil.java:61)
	at com.hl95.common.controller.SmsManageController.propelSms(SmsManageController.java:79)
	at sun.reflect.NativeMethodAccessorImpl.invoke0(Native Method)
	at sun.reflect.NativeMethodAccessorImpl.invoke(NativeMethodAccessorImpl.java:62)
	at sun.reflect.DelegatingMethodAccessorImpl.invoke(DelegatingMethodAccessorImpl.java:43)
	at java.lang.reflect.Method.invoke(Method.java:498)
	at org.springframework.scheduling.support.ScheduledMethodRunnable.run(ScheduledMethodRunnable.java:65)
	at org.springframework.scheduling.support.DelegatingErrorHandlingRunnable.run(DelegatingErrorHandlingRunnable.java:54)
	at java.util.concurrent.Executors$RunnableAdapter.call(Executors.java:511)
	at java.util.concurrent.FutureTask.runAndReset(FutureTask.java:308)
	at java.util.concurrent.ScheduledThreadPoolExecutor$ScheduledFutureTask.access$301(ScheduledThreadPoolExecutor.java:180)
	at java.util.concurrent.ScheduledThreadPoolExecutor$ScheduledFutureTask.run(ScheduledThreadPoolExecutor.java:294)
	at java.util.concurrent.ThreadPoolExecutor.runWorker(ThreadPoolExecutor.java:1149)
	at java.util.concurrent.ThreadPoolExecutor$Worker.run(ThreadPoolExecutor.java:624)
	at java.lang.Thread.run(Thread.java:748)
Caused by: com.mysql.jdbc.exceptions.jdbc4.MySQLSyntaxErrorException: Access denied for user 'hljw'@'%' to database 'hl_jw'
	at sun.reflect.NativeConstructorAccessorImpl.newInstance0(Native Method)
	at sun.reflect.NativeConstructorAccessorImpl.newInstance(NativeConstructorAccessorImpl.java:62)
	at sun.reflect.DelegatingConstructorAccessorImpl.newInstance(DelegatingConstructorAccessorImpl.java:45)
	at java.lang.reflect.Constructor.newInstance(Constructor.java:423)
	at com.mysql.jdbc.Util.handleNewInstance(Util.java:377)
	at com.mysql.jdbc.Util.getInstance(Util.java:360)
	at com.mysql.jdbc.SQLError.createSQLException(SQLError.java:978)
	at com.mysql.jdbc.MysqlIO.checkErrorPacket(MysqlIO.java:3887)
	at com.mysql.jdbc.MysqlIO.checkErrorPacket(MysqlIO.java:3823)
	at com.mysql.jdbc.MysqlIO.checkErrorPacket(MysqlIO.java:870)
	at com.mysql.jdbc.MysqlIO.proceedHandshakeWithPluggableAuthentication(MysqlIO.java:1659)
	at com.mysql.jdbc.MysqlIO.doHandshake(MysqlIO.java:1206)
	at com.mysql.jdbc.ConnectionImpl.coreConnect(ConnectionImpl.java:2234)
	at com.mysql.jdbc.ConnectionImpl.connectOneTryOnly(ConnectionImpl.java:2265)
	at com.mysql.jdbc.ConnectionImpl.createNewIO(ConnectionImpl.java:2064)
	at com.mysql.jdbc.ConnectionImpl.<init>(ConnectionImpl.java:790)
	at com.mysql.jdbc.JDBC4Connection.<init>(JDBC4Connection.java:44)
	at sun.reflect.NativeConstructorAccessorImpl.newInstance0(Native Method)
	at sun.reflect.NativeConstructorAccessorImpl.newInstance(NativeConstructorAccessorImpl.java:62)
	at sun.reflect.DelegatingConstructorAccessorImpl.newInstance(DelegatingConstructorAccessorImpl.java:45)
	at java.lang.reflect.Constructor.newInstance(Constructor.java:423)
	at com.mysql.jdbc.Util.handleNewInstance(Util.java:377)
	at com.mysql.jdbc.ConnectionImpl.getInstance(ConnectionImpl.java:395)
	at com.mysql.jdbc.NonRegisteringDriver.connect(NonRegisteringDriver.java:325)
	at java.sql.DriverManager.getConnection(DriverManager.java:664)
	at java.sql.DriverManager.getConnection(DriverManager.java:247)
	at com.hl95.utils.JdbcUtil.getConnection(JdbcUtil.java:59)
	... 14 more
[ERROR][2018-05-25 08:50:17,943][org.springframework.scheduling.support.TaskUtils$LoggingErrorHandler]Unexpected error occurred in scheduled task.
java.lang.RuntimeException: get connection error!
	at com.hl95.utils.JdbcUtil.getConnection(JdbcUtil.java:61)
	at com.hl95.common.controller.SmsManageController.propelSms(SmsManageController.java:79)
	at sun.reflect.NativeMethodAccessorImpl.invoke0(Native Method)
	at sun.reflect.NativeMethodAccessorImpl.invoke(NativeMethodAccessorImpl.java:62)
	at sun.reflect.DelegatingMethodAccessorImpl.invoke(DelegatingMethodAccessorImpl.java:43)
	at java.lang.reflect.Method.invoke(Method.java:498)
	at org.springframework.scheduling.support.ScheduledMethodRunnable.run(ScheduledMethodRunnable.java:65)
	at org.springframework.scheduling.support.DelegatingErrorHandlingRunnable.run(DelegatingErrorHandlingRunnable.java:54)
	at java.util.concurrent.Executors$RunnableAdapter.call(Executors.java:511)
	at java.util.concurrent.FutureTask.runAndReset(FutureTask.java:308)
	at java.util.concurrent.ScheduledThreadPoolExecutor$ScheduledFutureTask.access$301(ScheduledThreadPoolExecutor.java:180)
	at java.util.concurrent.ScheduledThreadPoolExecutor$ScheduledFutureTask.run(ScheduledThreadPoolExecutor.java:294)
	at java.util.concurrent.ThreadPoolExecutor.runWorker(ThreadPoolExecutor.java:1149)
	at java.util.concurrent.ThreadPoolExecutor$Worker.run(ThreadPoolExecutor.java:624)
	at java.lang.Thread.run(Thread.java:748)
Caused by: com.mysql.jdbc.exceptions.jdbc4.MySQLSyntaxErrorException: Access denied for user 'hljw'@'%' to database 'hl_jw'
	at sun.reflect.NativeConstructorAccessorImpl.newInstance0(Native Method)
	at sun.reflect.NativeConstructorAccessorImpl.newInstance(NativeConstructorAccessorImpl.java:62)
	at sun.reflect.DelegatingConstructorAccessorImpl.newInstance(DelegatingConstructorAccessorImpl.java:45)
	at java.lang.reflect.Constructor.newInstance(Constructor.java:423)
	at com.mysql.jdbc.Util.handleNewInstance(Util.java:377)
	at com.mysql.jdbc.Util.getInstance(Util.java:360)
	at com.mysql.jdbc.SQLError.createSQLException(SQLError.java:978)
	at com.mysql.jdbc.MysqlIO.checkErrorPacket(MysqlIO.java:3887)
	at com.mysql.jdbc.MysqlIO.checkErrorPacket(MysqlIO.java:3823)
	at com.mysql.jdbc.MysqlIO.checkErrorPacket(MysqlIO.java:870)
	at com.mysql.jdbc.MysqlIO.proceedHandshakeWithPluggableAuthentication(MysqlIO.java:1659)
	at com.mysql.jdbc.MysqlIO.doHandshake(MysqlIO.java:1206)
	at com.mysql.jdbc.ConnectionImpl.coreConnect(ConnectionImpl.java:2234)
	at com.mysql.jdbc.ConnectionImpl.connectOneTryOnly(ConnectionImpl.java:2265)
	at com.mysql.jdbc.ConnectionImpl.createNewIO(ConnectionImpl.java:2064)
	at com.mysql.jdbc.ConnectionImpl.<init>(ConnectionImpl.java:790)
	at com.mysql.jdbc.JDBC4Connection.<init>(JDBC4Connection.java:44)
	at sun.reflect.NativeConstructorAccessorImpl.newInstance0(Native Method)
	at sun.reflect.NativeConstructorAccessorImpl.newInstance(NativeConstructorAccessorImpl.java:62)
	at sun.reflect.DelegatingConstructorAccessorImpl.newInstance(DelegatingConstructorAccessorImpl.java:45)
	at java.lang.reflect.Constructor.newInstance(Constructor.java:423)
	at com.mysql.jdbc.Util.handleNewInstance(Util.java:377)
	at com.mysql.jdbc.ConnectionImpl.getInstance(ConnectionImpl.java:395)
	at com.mysql.jdbc.NonRegisteringDriver.connect(NonRegisteringDriver.java:325)
	at java.sql.DriverManager.getConnection(DriverManager.java:664)
	at java.sql.DriverManager.getConnection(DriverManager.java:247)
	at com.hl95.utils.JdbcUtil.getConnection(JdbcUtil.java:59)
	... 14 more
[ERROR][2018-05-25 08:50:18,948][org.springframework.scheduling.support.TaskUtils$LoggingErrorHandler]Unexpected error occurred in scheduled task.
java.lang.RuntimeException: get connection error!
	at com.hl95.utils.JdbcUtil.getConnection(JdbcUtil.java:61)
	at com.hl95.common.controller.SmsManageController.propelSms(SmsManageController.java:79)
	at sun.reflect.NativeMethodAccessorImpl.invoke0(Native Method)
	at sun.reflect.NativeMethodAccessorImpl.invoke(NativeMethodAccessorImpl.java:62)
	at sun.reflect.DelegatingMethodAccessorImpl.invoke(DelegatingMethodAccessorImpl.java:43)
	at java.lang.reflect.Method.invoke(Method.java:498)
	at org.springframework.scheduling.support.ScheduledMethodRunnable.run(ScheduledMethodRunnable.java:65)
	at org.springframework.scheduling.support.DelegatingErrorHandlingRunnable.run(DelegatingErrorHandlingRunnable.java:54)
	at java.util.concurrent.Executors$RunnableAdapter.call(Executors.java:511)
	at java.util.concurrent.FutureTask.runAndReset(FutureTask.java:308)
	at java.util.concurrent.ScheduledThreadPoolExecutor$ScheduledFutureTask.access$301(ScheduledThreadPoolExecutor.java:180)
	at java.util.concurrent.ScheduledThreadPoolExecutor$ScheduledFutureTask.run(ScheduledThreadPoolExecutor.java:294)
	at java.util.concurrent.ThreadPoolExecutor.runWorker(ThreadPoolExecutor.java:1149)
	at java.util.concurrent.ThreadPoolExecutor$Worker.run(ThreadPoolExecutor.java:624)
	at java.lang.Thread.run(Thread.java:748)
Caused by: com.mysql.jdbc.exceptions.jdbc4.MySQLSyntaxErrorException: Access denied for user 'hljw'@'%' to database 'hl_jw'
	at sun.reflect.NativeConstructorAccessorImpl.newInstance0(Native Method)
	at sun.reflect.NativeConstructorAccessorImpl.newInstance(NativeConstructorAccessorImpl.java:62)
	at sun.reflect.DelegatingConstructorAccessorImpl.newInstance(DelegatingConstructorAccessorImpl.java:45)
	at java.lang.reflect.Constructor.newInstance(Constructor.java:423)
	at com.mysql.jdbc.Util.handleNewInstance(Util.java:377)
	at com.mysql.jdbc.Util.getInstance(Util.java:360)
	at com.mysql.jdbc.SQLError.createSQLException(SQLError.java:978)
	at com.mysql.jdbc.MysqlIO.checkErrorPacket(MysqlIO.java:3887)
	at com.mysql.jdbc.MysqlIO.checkErrorPacket(MysqlIO.java:3823)
	at com.mysql.jdbc.MysqlIO.checkErrorPacket(MysqlIO.java:870)
	at com.mysql.jdbc.MysqlIO.proceedHandshakeWithPluggableAuthentication(MysqlIO.java:1659)
	at com.mysql.jdbc.MysqlIO.doHandshake(MysqlIO.java:1206)
	at com.mysql.jdbc.ConnectionImpl.coreConnect(ConnectionImpl.java:2234)
	at com.mysql.jdbc.ConnectionImpl.connectOneTryOnly(ConnectionImpl.java:2265)
	at com.mysql.jdbc.ConnectionImpl.createNewIO(ConnectionImpl.java:2064)
	at com.mysql.jdbc.ConnectionImpl.<init>(ConnectionImpl.java:790)
	at com.mysql.jdbc.JDBC4Connection.<init>(JDBC4Connection.java:44)
	at sun.reflect.NativeConstructorAccessorImpl.newInstance0(Native Method)
	at sun.reflect.NativeConstructorAccessorImpl.newInstance(NativeConstructorAccessorImpl.java:62)
	at sun.reflect.DelegatingConstructorAccessorImpl.newInstance(DelegatingConstructorAccessorImpl.java:45)
	at java.lang.reflect.Constructor.newInstance(Constructor.java:423)
	at com.mysql.jdbc.Util.handleNewInstance(Util.java:377)
	at com.mysql.jdbc.ConnectionImpl.getInstance(ConnectionImpl.java:395)
	at com.mysql.jdbc.NonRegisteringDriver.connect(NonRegisteringDriver.java:325)
	at java.sql.DriverManager.getConnection(DriverManager.java:664)
	at java.sql.DriverManager.getConnection(DriverManager.java:247)
	at com.hl95.utils.JdbcUtil.getConnection(JdbcUtil.java:59)
	... 14 more
[ERROR][2018-05-25 08:50:19,933][org.springframework.scheduling.support.TaskUtils$LoggingErrorHandler]Unexpected error occurred in scheduled task.
java.lang.RuntimeException: get connection error!
	at com.hl95.utils.JdbcUtil.getConnection(JdbcUtil.java:61)
	at com.hl95.common.controller.SmsManageController.propelSms(SmsManageController.java:79)
	at sun.reflect.NativeMethodAccessorImpl.invoke0(Native Method)
	at sun.reflect.NativeMethodAccessorImpl.invoke(NativeMethodAccessorImpl.java:62)
	at sun.reflect.DelegatingMethodAccessorImpl.invoke(DelegatingMethodAccessorImpl.java:43)
	at java.lang.reflect.Method.invoke(Method.java:498)
	at org.springframework.scheduling.support.ScheduledMethodRunnable.run(ScheduledMethodRunnable.java:65)
	at org.springframework.scheduling.support.DelegatingErrorHandlingRunnable.run(DelegatingErrorHandlingRunnable.java:54)
	at java.util.concurrent.Executors$RunnableAdapter.call(Executors.java:511)
	at java.util.concurrent.FutureTask.runAndReset(FutureTask.java:308)
	at java.util.concurrent.ScheduledThreadPoolExecutor$ScheduledFutureTask.access$301(ScheduledThreadPoolExecutor.java:180)
	at java.util.concurrent.ScheduledThreadPoolExecutor$ScheduledFutureTask.run(ScheduledThreadPoolExecutor.java:294)
	at java.util.concurrent.ThreadPoolExecutor.runWorker(ThreadPoolExecutor.java:1149)
	at java.util.concurrent.ThreadPoolExecutor$Worker.run(ThreadPoolExecutor.java:624)
	at java.lang.Thread.run(Thread.java:748)
Caused by: com.mysql.jdbc.exceptions.jdbc4.MySQLSyntaxErrorException: Access denied for user 'hljw'@'%' to database 'hl_jw'
	at sun.reflect.NativeConstructorAccessorImpl.newInstance0(Native Method)
	at sun.reflect.NativeConstructorAccessorImpl.newInstance(NativeConstructorAccessorImpl.java:62)
	at sun.reflect.DelegatingConstructorAccessorImpl.newInstance(DelegatingConstructorAccessorImpl.java:45)
	at java.lang.reflect.Constructor.newInstance(Constructor.java:423)
	at com.mysql.jdbc.Util.handleNewInstance(Util.java:377)
	at com.mysql.jdbc.Util.getInstance(Util.java:360)
	at com.mysql.jdbc.SQLError.createSQLException(SQLError.java:978)
	at com.mysql.jdbc.MysqlIO.checkErrorPacket(MysqlIO.java:3887)
	at com.mysql.jdbc.MysqlIO.checkErrorPacket(MysqlIO.java:3823)
	at com.mysql.jdbc.MysqlIO.checkErrorPacket(MysqlIO.java:870)
	at com.mysql.jdbc.MysqlIO.proceedHandshakeWithPluggableAuthentication(MysqlIO.java:1659)
	at com.mysql.jdbc.MysqlIO.doHandshake(MysqlIO.java:1206)
	at com.mysql.jdbc.ConnectionImpl.coreConnect(ConnectionImpl.java:2234)
	at com.mysql.jdbc.ConnectionImpl.connectOneTryOnly(ConnectionImpl.java:2265)
	at com.mysql.jdbc.ConnectionImpl.createNewIO(ConnectionImpl.java:2064)
	at com.mysql.jdbc.ConnectionImpl.<init>(ConnectionImpl.java:790)
	at com.mysql.jdbc.JDBC4Connection.<init>(JDBC4Connection.java:44)
	at sun.reflect.NativeConstructorAccessorImpl.newInstance0(Native Method)
	at sun.reflect.NativeConstructorAccessorImpl.newInstance(NativeConstructorAccessorImpl.java:62)
	at sun.reflect.DelegatingConstructorAccessorImpl.newInstance(DelegatingConstructorAccessorImpl.java:45)
	at java.lang.reflect.Constructor.newInstance(Constructor.java:423)
	at com.mysql.jdbc.Util.handleNewInstance(Util.java:377)
	at com.mysql.jdbc.ConnectionImpl.getInstance(ConnectionImpl.java:395)
	at com.mysql.jdbc.NonRegisteringDriver.connect(NonRegisteringDriver.java:325)
	at java.sql.DriverManager.getConnection(DriverManager.java:664)
	at java.sql.DriverManager.getConnection(DriverManager.java:247)
	at com.hl95.utils.JdbcUtil.getConnection(JdbcUtil.java:59)
	... 14 more
[ERROR][2018-05-25 08:50:20,936][org.springframework.scheduling.support.TaskUtils$LoggingErrorHandler]Unexpected error occurred in scheduled task.
java.lang.RuntimeException: get connection error!
	at com.hl95.utils.JdbcUtil.getConnection(JdbcUtil.java:61)
	at com.hl95.common.controller.SmsManageController.propelSms(SmsManageController.java:79)
	at sun.reflect.NativeMethodAccessorImpl.invoke0(Native Method)
	at sun.reflect.NativeMethodAccessorImpl.invoke(NativeMethodAccessorImpl.java:62)
	at sun.reflect.DelegatingMethodAccessorImpl.invoke(DelegatingMethodAccessorImpl.java:43)
	at java.lang.reflect.Method.invoke(Method.java:498)
	at org.springframework.scheduling.support.ScheduledMethodRunnable.run(ScheduledMethodRunnable.java:65)
	at org.springframework.scheduling.support.DelegatingErrorHandlingRunnable.run(DelegatingErrorHandlingRunnable.java:54)
	at java.util.concurrent.Executors$RunnableAdapter.call(Executors.java:511)
	at java.util.concurrent.FutureTask.runAndReset(FutureTask.java:308)
	at java.util.concurrent.ScheduledThreadPoolExecutor$ScheduledFutureTask.access$301(ScheduledThreadPoolExecutor.java:180)
	at java.util.concurrent.ScheduledThreadPoolExecutor$ScheduledFutureTask.run(ScheduledThreadPoolExecutor.java:294)
	at java.util.concurrent.ThreadPoolExecutor.runWorker(ThreadPoolExecutor.java:1149)
	at java.util.concurrent.ThreadPoolExecutor$Worker.run(ThreadPoolExecutor.java:624)
	at java.lang.Thread.run(Thread.java:748)
Caused by: com.mysql.jdbc.exceptions.jdbc4.MySQLSyntaxErrorException: Access denied for user 'hljw'@'%' to database 'hl_jw'
	at sun.reflect.NativeConstructorAccessorImpl.newInstance0(Native Method)
	at sun.reflect.NativeConstructorAccessorImpl.newInstance(NativeConstructorAccessorImpl.java:62)
	at sun.reflect.DelegatingConstructorAccessorImpl.newInstance(DelegatingConstructorAccessorImpl.java:45)
	at java.lang.reflect.Constructor.newInstance(Constructor.java:423)
	at com.mysql.jdbc.Util.handleNewInstance(Util.java:377)
	at com.mysql.jdbc.Util.getInstance(Util.java:360)
	at com.mysql.jdbc.SQLError.createSQLException(SQLError.java:978)
	at com.mysql.jdbc.MysqlIO.checkErrorPacket(MysqlIO.java:3887)
	at com.mysql.jdbc.MysqlIO.checkErrorPacket(MysqlIO.java:3823)
	at com.mysql.jdbc.MysqlIO.checkErrorPacket(MysqlIO.java:870)
	at com.mysql.jdbc.MysqlIO.proceedHandshakeWithPluggableAuthentication(MysqlIO.java:1659)
	at com.mysql.jdbc.MysqlIO.doHandshake(MysqlIO.java:1206)
	at com.mysql.jdbc.ConnectionImpl.coreConnect(ConnectionImpl.java:2234)
	at com.mysql.jdbc.ConnectionImpl.connectOneTryOnly(ConnectionImpl.java:2265)
	at com.mysql.jdbc.ConnectionImpl.createNewIO(ConnectionImpl.java:2064)
	at com.mysql.jdbc.ConnectionImpl.<init>(ConnectionImpl.java:790)
	at com.mysql.jdbc.JDBC4Connection.<init>(JDBC4Connection.java:44)
	at sun.reflect.NativeConstructorAccessorImpl.newInstance0(Native Method)
	at sun.reflect.NativeConstructorAccessorImpl.newInstance(NativeConstructorAccessorImpl.java:62)
	at sun.reflect.DelegatingConstructorAccessorImpl.newInstance(DelegatingConstructorAccessorImpl.java:45)
	at java.lang.reflect.Constructor.newInstance(Constructor.java:423)
	at com.mysql.jdbc.Util.handleNewInstance(Util.java:377)
	at com.mysql.jdbc.ConnectionImpl.getInstance(ConnectionImpl.java:395)
	at com.mysql.jdbc.NonRegisteringDriver.connect(NonRegisteringDriver.java:325)
	at java.sql.DriverManager.getConnection(DriverManager.java:664)
	at java.sql.DriverManager.getConnection(DriverManager.java:247)
	at com.hl95.utils.JdbcUtil.getConnection(JdbcUtil.java:59)
	... 14 more
[ERROR][2018-05-25 08:50:21,937][org.springframework.scheduling.support.TaskUtils$LoggingErrorHandler]Unexpected error occurred in scheduled task.
java.lang.RuntimeException: get connection error!
	at com.hl95.utils.JdbcUtil.getConnection(JdbcUtil.java:61)
	at com.hl95.common.controller.SmsManageController.propelSms(SmsManageController.java:79)
	at sun.reflect.NativeMethodAccessorImpl.invoke0(Native Method)
	at sun.reflect.NativeMethodAccessorImpl.invoke(NativeMethodAccessorImpl.java:62)
	at sun.reflect.DelegatingMethodAccessorImpl.invoke(DelegatingMethodAccessorImpl.java:43)
	at java.lang.reflect.Method.invoke(Method.java:498)
	at org.springframework.scheduling.support.ScheduledMethodRunnable.run(ScheduledMethodRunnable.java:65)
	at org.springframework.scheduling.support.DelegatingErrorHandlingRunnable.run(DelegatingErrorHandlingRunnable.java:54)
	at java.util.concurrent.Executors$RunnableAdapter.call(Executors.java:511)
	at java.util.concurrent.FutureTask.runAndReset(FutureTask.java:308)
	at java.util.concurrent.ScheduledThreadPoolExecutor$ScheduledFutureTask.access$301(ScheduledThreadPoolExecutor.java:180)
	at java.util.concurrent.ScheduledThreadPoolExecutor$ScheduledFutureTask.run(ScheduledThreadPoolExecutor.java:294)
	at java.util.concurrent.ThreadPoolExecutor.runWorker(ThreadPoolExecutor.java:1149)
	at java.util.concurrent.ThreadPoolExecutor$Worker.run(ThreadPoolExecutor.java:624)
	at java.lang.Thread.run(Thread.java:748)
Caused by: com.mysql.jdbc.exceptions.jdbc4.MySQLSyntaxErrorException: Access denied for user 'hljw'@'%' to database 'hl_jw'
	at sun.reflect.NativeConstructorAccessorImpl.newInstance0(Native Method)
	at sun.reflect.NativeConstructorAccessorImpl.newInstance(NativeConstructorAccessorImpl.java:62)
	at sun.reflect.DelegatingConstructorAccessorImpl.newInstance(DelegatingConstructorAccessorImpl.java:45)
	at java.lang.reflect.Constructor.newInstance(Constructor.java:423)
	at com.mysql.jdbc.Util.handleNewInstance(Util.java:377)
	at com.mysql.jdbc.Util.getInstance(Util.java:360)
	at com.mysql.jdbc.SQLError.createSQLException(SQLError.java:978)
	at com.mysql.jdbc.MysqlIO.checkErrorPacket(MysqlIO.java:3887)
	at com.mysql.jdbc.MysqlIO.checkErrorPacket(MysqlIO.java:3823)
	at com.mysql.jdbc.MysqlIO.checkErrorPacket(MysqlIO.java:870)
	at com.mysql.jdbc.MysqlIO.proceedHandshakeWithPluggableAuthentication(MysqlIO.java:1659)
	at com.mysql.jdbc.MysqlIO.doHandshake(MysqlIO.java:1206)
	at com.mysql.jdbc.ConnectionImpl.coreConnect(ConnectionImpl.java:2234)
	at com.mysql.jdbc.ConnectionImpl.connectOneTryOnly(ConnectionImpl.java:2265)
	at com.mysql.jdbc.ConnectionImpl.createNewIO(ConnectionImpl.java:2064)
	at com.mysql.jdbc.ConnectionImpl.<init>(ConnectionImpl.java:790)
	at com.mysql.jdbc.JDBC4Connection.<init>(JDBC4Connection.java:44)
	at sun.reflect.NativeConstructorAccessorImpl.newInstance0(Native Method)
	at sun.reflect.NativeConstructorAccessorImpl.newInstance(NativeConstructorAccessorImpl.java:62)
	at sun.reflect.DelegatingConstructorAccessorImpl.newInstance(DelegatingConstructorAccessorImpl.java:45)
	at java.lang.reflect.Constructor.newInstance(Constructor.java:423)
	at com.mysql.jdbc.Util.handleNewInstance(Util.java:377)
	at com.mysql.jdbc.ConnectionImpl.getInstance(ConnectionImpl.java:395)
	at com.mysql.jdbc.NonRegisteringDriver.connect(NonRegisteringDriver.java:325)
	at java.sql.DriverManager.getConnection(DriverManager.java:664)
	at java.sql.DriverManager.getConnection(DriverManager.java:247)
	at com.hl95.utils.JdbcUtil.getConnection(JdbcUtil.java:59)
	... 14 more
[ERROR][2018-05-25 08:50:22,938][org.springframework.scheduling.support.TaskUtils$LoggingErrorHandler]Unexpected error occurred in scheduled task.
java.lang.RuntimeException: get connection error!
	at com.hl95.utils.JdbcUtil.getConnection(JdbcUtil.java:61)
	at com.hl95.common.controller.SmsManageController.propelSms(SmsManageController.java:79)
	at sun.reflect.NativeMethodAccessorImpl.invoke0(Native Method)
	at sun.reflect.NativeMethodAccessorImpl.invoke(NativeMethodAccessorImpl.java:62)
	at sun.reflect.DelegatingMethodAccessorImpl.invoke(DelegatingMethodAccessorImpl.java:43)
	at java.lang.reflect.Method.invoke(Method.java:498)
	at org.springframework.scheduling.support.ScheduledMethodRunnable.run(ScheduledMethodRunnable.java:65)
	at org.springframework.scheduling.support.DelegatingErrorHandlingRunnable.run(DelegatingErrorHandlingRunnable.java:54)
	at java.util.concurrent.Executors$RunnableAdapter.call(Executors.java:511)
	at java.util.concurrent.FutureTask.runAndReset(FutureTask.java:308)
	at java.util.concurrent.ScheduledThreadPoolExecutor$ScheduledFutureTask.access$301(ScheduledThreadPoolExecutor.java:180)
	at java.util.concurrent.ScheduledThreadPoolExecutor$ScheduledFutureTask.run(ScheduledThreadPoolExecutor.java:294)
	at java.util.concurrent.ThreadPoolExecutor.runWorker(ThreadPoolExecutor.java:1149)
	at java.util.concurrent.ThreadPoolExecutor$Worker.run(ThreadPoolExecutor.java:624)
	at java.lang.Thread.run(Thread.java:748)
Caused by: com.mysql.jdbc.exceptions.jdbc4.MySQLSyntaxErrorException: Access denied for user 'hljw'@'%' to database 'hl_jw'
	at sun.reflect.NativeConstructorAccessorImpl.newInstance0(Native Method)
	at sun.reflect.NativeConstructorAccessorImpl.newInstance(NativeConstructorAccessorImpl.java:62)
	at sun.reflect.DelegatingConstructorAccessorImpl.newInstance(DelegatingConstructorAccessorImpl.java:45)
	at java.lang.reflect.Constructor.newInstance(Constructor.java:423)
	at com.mysql.jdbc.Util.handleNewInstance(Util.java:377)
	at com.mysql.jdbc.Util.getInstance(Util.java:360)
	at com.mysql.jdbc.SQLError.createSQLException(SQLError.java:978)
	at com.mysql.jdbc.MysqlIO.checkErrorPacket(MysqlIO.java:3887)
	at com.mysql.jdbc.MysqlIO.checkErrorPacket(MysqlIO.java:3823)
	at com.mysql.jdbc.MysqlIO.checkErrorPacket(MysqlIO.java:870)
	at com.mysql.jdbc.MysqlIO.proceedHandshakeWithPluggableAuthentication(MysqlIO.java:1659)
	at com.mysql.jdbc.MysqlIO.doHandshake(MysqlIO.java:1206)
	at com.mysql.jdbc.ConnectionImpl.coreConnect(ConnectionImpl.java:2234)
	at com.mysql.jdbc.ConnectionImpl.connectOneTryOnly(ConnectionImpl.java:2265)
	at com.mysql.jdbc.ConnectionImpl.createNewIO(ConnectionImpl.java:2064)
	at com.mysql.jdbc.ConnectionImpl.<init>(ConnectionImpl.java:790)
	at com.mysql.jdbc.JDBC4Connection.<init>(JDBC4Connection.java:44)
	at sun.reflect.NativeConstructorAccessorImpl.newInstance0(Native Method)
	at sun.reflect.NativeConstructorAccessorImpl.newInstance(NativeConstructorAccessorImpl.java:62)
	at sun.reflect.DelegatingConstructorAccessorImpl.newInstance(DelegatingConstructorAccessorImpl.java:45)
	at java.lang.reflect.Constructor.newInstance(Constructor.java:423)
	at com.mysql.jdbc.Util.handleNewInstance(Util.java:377)
	at com.mysql.jdbc.ConnectionImpl.getInstance(ConnectionImpl.java:395)
	at com.mysql.jdbc.NonRegisteringDriver.connect(NonRegisteringDriver.java:325)
	at java.sql.DriverManager.getConnection(DriverManager.java:664)
	at java.sql.DriverManager.getConnection(DriverManager.java:247)
	at com.hl95.utils.JdbcUtil.getConnection(JdbcUtil.java:59)
	... 14 more
[ERROR][2018-05-25 08:50:23,936][org.springframework.scheduling.support.TaskUtils$LoggingErrorHandler]Unexpected error occurred in scheduled task.
java.lang.RuntimeException: get connection error!
	at com.hl95.utils.JdbcUtil.getConnection(JdbcUtil.java:61)
	at com.hl95.common.controller.SmsManageController.propelSms(SmsManageController.java:79)
	at sun.reflect.NativeMethodAccessorImpl.invoke0(Native Method)
	at sun.reflect.NativeMethodAccessorImpl.invoke(NativeMethodAccessorImpl.java:62)
	at sun.reflect.DelegatingMethodAccessorImpl.invoke(DelegatingMethodAccessorImpl.java:43)
	at java.lang.reflect.Method.invoke(Method.java:498)
	at org.springframework.scheduling.support.ScheduledMethodRunnable.run(ScheduledMethodRunnable.java:65)
	at org.springframework.scheduling.support.DelegatingErrorHandlingRunnable.run(DelegatingErrorHandlingRunnable.java:54)
	at java.util.concurrent.Executors$RunnableAdapter.call(Executors.java:511)
	at java.util.concurrent.FutureTask.runAndReset(FutureTask.java:308)
	at java.util.concurrent.ScheduledThreadPoolExecutor$ScheduledFutureTask.access$301(ScheduledThreadPoolExecutor.java:180)
	at java.util.concurrent.ScheduledThreadPoolExecutor$ScheduledFutureTask.run(ScheduledThreadPoolExecutor.java:294)
	at java.util.concurrent.ThreadPoolExecutor.runWorker(ThreadPoolExecutor.java:1149)
	at java.util.concurrent.ThreadPoolExecutor$Worker.run(ThreadPoolExecutor.java:624)
	at java.lang.Thread.run(Thread.java:748)
Caused by: com.mysql.jdbc.exceptions.jdbc4.MySQLSyntaxErrorException: Access denied for user 'hljw'@'%' to database 'hl_jw'
	at sun.reflect.NativeConstructorAccessorImpl.newInstance0(Native Method)
	at sun.reflect.NativeConstructorAccessorImpl.newInstance(NativeConstructorAccessorImpl.java:62)
	at sun.reflect.DelegatingConstructorAccessorImpl.newInstance(DelegatingConstructorAccessorImpl.java:45)
	at java.lang.reflect.Constructor.newInstance(Constructor.java:423)
	at com.mysql.jdbc.Util.handleNewInstance(Util.java:377)
	at com.mysql.jdbc.Util.getInstance(Util.java:360)
	at com.mysql.jdbc.SQLError.createSQLException(SQLError.java:978)
	at com.mysql.jdbc.MysqlIO.checkErrorPacket(MysqlIO.java:3887)
	at com.mysql.jdbc.MysqlIO.checkErrorPacket(MysqlIO.java:3823)
	at com.mysql.jdbc.MysqlIO.checkErrorPacket(MysqlIO.java:870)
	at com.mysql.jdbc.MysqlIO.proceedHandshakeWithPluggableAuthentication(MysqlIO.java:1659)
	at com.mysql.jdbc.MysqlIO.doHandshake(MysqlIO.java:1206)
	at com.mysql.jdbc.ConnectionImpl.coreConnect(ConnectionImpl.java:2234)
	at com.mysql.jdbc.ConnectionImpl.connectOneTryOnly(ConnectionImpl.java:2265)
	at com.mysql.jdbc.ConnectionImpl.createNewIO(ConnectionImpl.java:2064)
	at com.mysql.jdbc.ConnectionImpl.<init>(ConnectionImpl.java:790)
	at com.mysql.jdbc.JDBC4Connection.<init>(JDBC4Connection.java:44)
	at sun.reflect.NativeConstructorAccessorImpl.newInstance0(Native Method)
	at sun.reflect.NativeConstructorAccessorImpl.newInstance(NativeConstructorAccessorImpl.java:62)
	at sun.reflect.DelegatingConstructorAccessorImpl.newInstance(DelegatingConstructorAccessorImpl.java:45)
	at java.lang.reflect.Constructor.newInstance(Constructor.java:423)
	at com.mysql.jdbc.Util.handleNewInstance(Util.java:377)
	at com.mysql.jdbc.ConnectionImpl.getInstance(ConnectionImpl.java:395)
	at com.mysql.jdbc.NonRegisteringDriver.connect(NonRegisteringDriver.java:325)
	at java.sql.DriverManager.getConnection(DriverManager.java:664)
	at java.sql.DriverManager.getConnection(DriverManager.java:247)
	at com.hl95.utils.JdbcUtil.getConnection(JdbcUtil.java:59)
	... 14 more
[ERROR][2018-05-25 13:21:17,050][org.springframework.scheduling.support.TaskUtils$LoggingErrorHandler]Unexpected error occurred in scheduled task.
java.lang.NullPointerException
	at com.hl95.common.controller.SmsManageController.propelSms(SmsManageController.java:103)
	at sun.reflect.GeneratedMethodAccessor7.invoke(Unknown Source)
	at sun.reflect.DelegatingMethodAccessorImpl.invoke(DelegatingMethodAccessorImpl.java:43)
	at java.lang.reflect.Method.invoke(Method.java:498)
	at org.springframework.scheduling.support.ScheduledMethodRunnable.run(ScheduledMethodRunnable.java:65)
	at org.springframework.scheduling.support.DelegatingErrorHandlingRunnable.run(DelegatingErrorHandlingRunnable.java:54)
	at java.util.concurrent.Executors$RunnableAdapter.call(Executors.java:511)
	at java.util.concurrent.FutureTask.runAndReset(FutureTask.java:308)
	at java.util.concurrent.ScheduledThreadPoolExecutor$ScheduledFutureTask.access$301(ScheduledThreadPoolExecutor.java:180)
	at java.util.concurrent.ScheduledThreadPoolExecutor$ScheduledFutureTask.run(ScheduledThreadPoolExecutor.java:294)
	at java.util.concurrent.ThreadPoolExecutor.runWorker(ThreadPoolExecutor.java:1149)
	at java.util.concurrent.ThreadPoolExecutor$Worker.run(ThreadPoolExecutor.java:624)
	at java.lang.Thread.run(Thread.java:748)
[ERROR][2018-05-25 15:17:22,924][com.hl95.common.controller.SmsManageController]数据提交失败！
java.sql.SQLException: Generated keys not requested. You need to specify Statement.RETURN_GENERATED_KEYS to Statement.executeUpdate() or Connection.prepareStatement().
	at com.mysql.jdbc.SQLError.createSQLException(SQLError.java:996)
	at com.mysql.jdbc.SQLError.createSQLException(SQLError.java:935)
	at com.mysql.jdbc.SQLError.createSQLException(SQLError.java:924)
	at com.mysql.jdbc.SQLError.createSQLException(SQLError.java:870)
	at com.mysql.jdbc.StatementImpl.getGeneratedKeys(StatementImpl.java:1817)
	at com.hl95.common.controller.SmsManageController.propelSms(SmsManageController.java:115)
	at sun.reflect.GeneratedMethodAccessor7.invoke(Unknown Source)
	at sun.reflect.DelegatingMethodAccessorImpl.invoke(DelegatingMethodAccessorImpl.java:43)
	at java.lang.reflect.Method.invoke(Method.java:498)
	at org.springframework.scheduling.support.ScheduledMethodRunnable.run(ScheduledMethodRunnable.java:65)
	at org.springframework.scheduling.support.DelegatingErrorHandlingRunnable.run(DelegatingErrorHandlingRunnable.java:54)
	at java.util.concurrent.Executors$RunnableAdapter.call(Executors.java:511)
	at java.util.concurrent.FutureTask.runAndReset(FutureTask.java:308)
	at java.util.concurrent.ScheduledThreadPoolExecutor$ScheduledFutureTask.access$301(ScheduledThreadPoolExecutor.java:180)
	at java.util.concurrent.ScheduledThreadPoolExecutor$ScheduledFutureTask.run(ScheduledThreadPoolExecutor.java:294)
	at java.util.concurrent.ThreadPoolExecutor.runWorker(ThreadPoolExecutor.java:1149)
	at java.util.concurrent.ThreadPoolExecutor$Worker.run(ThreadPoolExecutor.java:624)
	at java.lang.Thread.run(Thread.java:748)
[ERROR][2018-05-25 15:17:27,176][com.hl95.common.controller.SmsManageController]数据提交失败！
java.sql.SQLException: Generated keys not requested. You need to specify Statement.RETURN_GENERATED_KEYS to Statement.executeUpdate() or Connection.prepareStatement().
	at com.mysql.jdbc.SQLError.createSQLException(SQLError.java:996)
	at com.mysql.jdbc.SQLError.createSQLException(SQLError.java:935)
	at com.mysql.jdbc.SQLError.createSQLException(SQLError.java:924)
	at com.mysql.jdbc.SQLError.createSQLException(SQLError.java:870)
	at com.mysql.jdbc.StatementImpl.getGeneratedKeys(StatementImpl.java:1817)
	at com.hl95.common.controller.SmsManageController.propelSms(SmsManageController.java:115)
	at sun.reflect.GeneratedMethodAccessor7.invoke(Unknown Source)
	at sun.reflect.DelegatingMethodAccessorImpl.invoke(DelegatingMethodAccessorImpl.java:43)
	at java.lang.reflect.Method.invoke(Method.java:498)
	at org.springframework.scheduling.support.ScheduledMethodRunnable.run(ScheduledMethodRunnable.java:65)
	at org.springframework.scheduling.support.DelegatingErrorHandlingRunnable.run(DelegatingErrorHandlingRunnable.java:54)
	at java.util.concurrent.Executors$RunnableAdapter.call(Executors.java:511)
	at java.util.concurrent.FutureTask.runAndReset(FutureTask.java:308)
	at java.util.concurrent.ScheduledThreadPoolExecutor$ScheduledFutureTask.access$301(ScheduledThreadPoolExecutor.java:180)
	at java.util.concurrent.ScheduledThreadPoolExecutor$ScheduledFutureTask.run(ScheduledThreadPoolExecutor.java:294)
	at java.util.concurrent.ThreadPoolExecutor.runWorker(ThreadPoolExecutor.java:1149)
	at java.util.concurrent.ThreadPoolExecutor$Worker.run(ThreadPoolExecutor.java:624)
	at java.lang.Thread.run(Thread.java:748)
[ERROR][2018-05-25 15:38:07,462][com.hl95.common.controller.SmsManageController]数据提交失败！
java.sql.SQLException: Generated keys not requested. You need to specify Statement.RETURN_GENERATED_KEYS to Statement.executeUpdate() or Connection.prepareStatement().
	at com.mysql.jdbc.SQLError.createSQLException(SQLError.java:996)
	at com.mysql.jdbc.SQLError.createSQLException(SQLError.java:935)
	at com.mysql.jdbc.SQLError.createSQLException(SQLError.java:924)
	at com.mysql.jdbc.SQLError.createSQLException(SQLError.java:870)
	at com.mysql.jdbc.StatementImpl.getGeneratedKeys(StatementImpl.java:1817)
	at com.hl95.common.controller.SmsManageController.propelSms(SmsManageController.java:116)
	at sun.reflect.GeneratedMethodAccessor7.invoke(Unknown Source)
	at sun.reflect.DelegatingMethodAccessorImpl.invoke(DelegatingMethodAccessorImpl.java:43)
	at java.lang.reflect.Method.invoke(Method.java:498)
	at org.springframework.scheduling.support.ScheduledMethodRunnable.run(ScheduledMethodRunnable.java:65)
	at org.springframework.scheduling.support.DelegatingErrorHandlingRunnable.run(DelegatingErrorHandlingRunnable.java:54)
	at java.util.concurrent.Executors$RunnableAdapter.call(Executors.java:511)
	at java.util.concurrent.FutureTask.runAndReset(FutureTask.java:308)
	at java.util.concurrent.ScheduledThreadPoolExecutor$ScheduledFutureTask.access$301(ScheduledThreadPoolExecutor.java:180)
	at java.util.concurrent.ScheduledThreadPoolExecutor$ScheduledFutureTask.run(ScheduledThreadPoolExecutor.java:294)
	at java.util.concurrent.ThreadPoolExecutor.runWorker(ThreadPoolExecutor.java:1149)
	at java.util.concurrent.ThreadPoolExecutor$Worker.run(ThreadPoolExecutor.java:624)
	at java.lang.Thread.run(Thread.java:748)
[ERROR][2018-05-25 15:57:23,973][com.hl95.common.controller.SmsManageController]数据提交失败！
java.sql.SQLException: Column 'BatchNo' not found.
	at com.mysql.jdbc.SQLError.createSQLException(SQLError.java:996)
	at com.mysql.jdbc.SQLError.createSQLException(SQLError.java:935)
	at com.mysql.jdbc.SQLError.createSQLException(SQLError.java:924)
	at com.mysql.jdbc.SQLError.createSQLException(SQLError.java:870)
	at com.mysql.jdbc.ResultSetImpl.findColumn(ResultSetImpl.java:1064)
	at com.mysql.jdbc.ResultSetImpl.getString(ResultSetImpl.java:5201)
	at com.hl95.common.controller.SmsManageController.propelSms(SmsManageController.java:120)
	at sun.reflect.GeneratedMethodAccessor8.invoke(Unknown Source)
	at sun.reflect.DelegatingMethodAccessorImpl.invoke(DelegatingMethodAccessorImpl.java:43)
	at java.lang.reflect.Method.invoke(Method.java:498)
	at org.springframework.scheduling.support.ScheduledMethodRunnable.run(ScheduledMethodRunnable.java:65)
	at org.springframework.scheduling.support.DelegatingErrorHandlingRunnable.run(DelegatingErrorHandlingRunnable.java:54)
	at java.util.concurrent.Executors$RunnableAdapter.call(Executors.java:511)
	at java.util.concurrent.FutureTask.runAndReset(FutureTask.java:308)
	at java.util.concurrent.ScheduledThreadPoolExecutor$ScheduledFutureTask.access$301(ScheduledThreadPoolExecutor.java:180)
	at java.util.concurrent.ScheduledThreadPoolExecutor$ScheduledFutureTask.run(ScheduledThreadPoolExecutor.java:294)
	at java.util.concurrent.ThreadPoolExecutor.runWorker(ThreadPoolExecutor.java:1149)
	at java.util.concurrent.ThreadPoolExecutor$Worker.run(ThreadPoolExecutor.java:624)
	at java.lang.Thread.run(Thread.java:748)
[ERROR][2018-05-25 15:58:04,719][com.hl95.common.controller.SmsManageController]数据提交失败！
java.sql.SQLException: Column 'BatchNo' not found.
	at com.mysql.jdbc.SQLError.createSQLException(SQLError.java:996)
	at com.mysql.jdbc.SQLError.createSQLException(SQLError.java:935)
	at com.mysql.jdbc.SQLError.createSQLException(SQLError.java:924)
	at com.mysql.jdbc.SQLError.createSQLException(SQLError.java:870)
	at com.mysql.jdbc.ResultSetImpl.findColumn(ResultSetImpl.java:1064)
	at com.mysql.jdbc.ResultSetImpl.getString(ResultSetImpl.java:5201)
	at com.hl95.common.controller.SmsManageController.propelSms(SmsManageController.java:120)
	at sun.reflect.GeneratedMethodAccessor7.invoke(Unknown Source)
	at sun.reflect.DelegatingMethodAccessorImpl.invoke(DelegatingMethodAccessorImpl.java:43)
	at java.lang.reflect.Method.invoke(Method.java:498)
	at org.springframework.scheduling.support.ScheduledMethodRunnable.run(ScheduledMethodRunnable.java:65)
	at org.springframework.scheduling.support.DelegatingErrorHandlingRunnable.run(DelegatingErrorHandlingRunnable.java:54)
	at java.util.concurrent.Executors$RunnableAdapter.call(Executors.java:511)
	at java.util.concurrent.FutureTask.runAndReset(FutureTask.java:308)
	at java.util.concurrent.ScheduledThreadPoolExecutor$ScheduledFutureTask.access$301(ScheduledThreadPoolExecutor.java:180)
	at java.util.concurrent.ScheduledThreadPoolExecutor$ScheduledFutureTask.run(ScheduledThreadPoolExecutor.java:294)
	at java.util.concurrent.ThreadPoolExecutor.runWorker(ThreadPoolExecutor.java:1149)
	at java.util.concurrent.ThreadPoolExecutor$Worker.run(ThreadPoolExecutor.java:624)
	at java.lang.Thread.run(Thread.java:748)
[ERROR][2018-05-25 16:01:25,721][com.hl95.common.controller.SmsManageController]数据提交失败！
java.sql.SQLException: Column 'BatchNo' not found.
	at com.mysql.jdbc.SQLError.createSQLException(SQLError.java:996)
	at com.mysql.jdbc.SQLError.createSQLException(SQLError.java:935)
	at com.mysql.jdbc.SQLError.createSQLException(SQLError.java:924)
	at com.mysql.jdbc.SQLError.createSQLException(SQLError.java:870)
	at com.mysql.jdbc.ResultSetImpl.findColumn(ResultSetImpl.java:1064)
	at com.mysql.jdbc.ResultSetImpl.getString(ResultSetImpl.java:5201)
	at com.hl95.common.controller.SmsManageController.propelSms(SmsManageController.java:120)
	at sun.reflect.GeneratedMethodAccessor7.invoke(Unknown Source)
	at sun.reflect.DelegatingMethodAccessorImpl.invoke(DelegatingMethodAccessorImpl.java:43)
	at java.lang.reflect.Method.invoke(Method.java:498)
	at org.springframework.scheduling.support.ScheduledMethodRunnable.run(ScheduledMethodRunnable.java:65)
	at org.springframework.scheduling.support.DelegatingErrorHandlingRunnable.run(DelegatingErrorHandlingRunnable.java:54)
	at java.util.concurrent.Executors$RunnableAdapter.call(Executors.java:511)
	at java.util.concurrent.FutureTask.runAndReset(FutureTask.java:308)
	at java.util.concurrent.ScheduledThreadPoolExecutor$ScheduledFutureTask.access$301(ScheduledThreadPoolExecutor.java:180)
	at java.util.concurrent.ScheduledThreadPoolExecutor$ScheduledFutureTask.run(ScheduledThreadPoolExecutor.java:294)
	at java.util.concurrent.ThreadPoolExecutor.runWorker(ThreadPoolExecutor.java:1149)
	at java.util.concurrent.ThreadPoolExecutor$Worker.run(ThreadPoolExecutor.java:624)
	at java.lang.Thread.run(Thread.java:748)
[ERROR][2018-05-25 16:13:36,705][com.hl95.common.controller.SmsManageController]数据提交失败！
java.sql.SQLException: Column 'BatchNo' not found.
	at com.mysql.jdbc.SQLError.createSQLException(SQLError.java:996)
	at com.mysql.jdbc.SQLError.createSQLException(SQLError.java:935)
	at com.mysql.jdbc.SQLError.createSQLException(SQLError.java:924)
	at com.mysql.jdbc.SQLError.createSQLException(SQLError.java:870)
	at com.mysql.jdbc.ResultSetImpl.findColumn(ResultSetImpl.java:1064)
	at com.mysql.jdbc.ResultSetImpl.getString(ResultSetImpl.java:5201)
	at com.hl95.common.controller.SmsManageController.propelSms(SmsManageController.java:120)
	at sun.reflect.GeneratedMethodAccessor7.invoke(Unknown Source)
	at sun.reflect.DelegatingMethodAccessorImpl.invoke(DelegatingMethodAccessorImpl.java:43)
	at java.lang.reflect.Method.invoke(Method.java:498)
	at org.springframework.scheduling.support.ScheduledMethodRunnable.run(ScheduledMethodRunnable.java:65)
	at org.springframework.scheduling.support.DelegatingErrorHandlingRunnable.run(DelegatingErrorHandlingRunnable.java:54)
	at java.util.concurrent.Executors$RunnableAdapter.call(Executors.java:511)
	at java.util.concurrent.FutureTask.runAndReset(FutureTask.java:308)
	at java.util.concurrent.ScheduledThreadPoolExecutor$ScheduledFutureTask.access$301(ScheduledThreadPoolExecutor.java:180)
	at java.util.concurrent.ScheduledThreadPoolExecutor$ScheduledFutureTask.run(ScheduledThreadPoolExecutor.java:294)
	at java.util.concurrent.ThreadPoolExecutor.runWorker(ThreadPoolExecutor.java:1149)
	at java.util.concurrent.ThreadPoolExecutor$Worker.run(ThreadPoolExecutor.java:624)
	at java.lang.Thread.run(Thread.java:748)
[ERROR][2018-05-25 16:15:39,138][com.hl95.common.controller.SmsManageController]数据提交失败！
java.sql.SQLException: Column Index out of range, 2 > 1. 
	at com.mysql.jdbc.SQLError.createSQLException(SQLError.java:996)
	at com.mysql.jdbc.SQLError.createSQLException(SQLError.java:935)
	at com.mysql.jdbc.SQLError.createSQLException(SQLError.java:924)
	at com.mysql.jdbc.SQLError.createSQLException(SQLError.java:870)
	at com.mysql.jdbc.ResultSetImpl.checkColumnBounds(ResultSetImpl.java:758)
	at com.mysql.jdbc.ResultSetImpl.getStringInternal(ResultSetImpl.java:5240)
	at com.mysql.jdbc.ResultSetImpl.getString(ResultSetImpl.java:5162)
	at com.hl95.common.controller.SmsManageController.propelSms(SmsManageController.java:120)
	at sun.reflect.GeneratedMethodAccessor7.invoke(Unknown Source)
	at sun.reflect.DelegatingMethodAccessorImpl.invoke(DelegatingMethodAccessorImpl.java:43)
	at java.lang.reflect.Method.invoke(Method.java:498)
	at org.springframework.scheduling.support.ScheduledMethodRunnable.run(ScheduledMethodRunnable.java:65)
	at org.springframework.scheduling.support.DelegatingErrorHandlingRunnable.run(DelegatingErrorHandlingRunnable.java:54)
	at java.util.concurrent.Executors$RunnableAdapter.call(Executors.java:511)
	at java.util.concurrent.FutureTask.runAndReset(FutureTask.java:308)
	at java.util.concurrent.ScheduledThreadPoolExecutor$ScheduledFutureTask.access$301(ScheduledThreadPoolExecutor.java:180)
	at java.util.concurrent.ScheduledThreadPoolExecutor$ScheduledFutureTask.run(ScheduledThreadPoolExecutor.java:294)
	at java.util.concurrent.ThreadPoolExecutor.runWorker(ThreadPoolExecutor.java:1149)
	at java.util.concurrent.ThreadPoolExecutor$Worker.run(ThreadPoolExecutor.java:624)
	at java.lang.Thread.run(Thread.java:748)
[ERROR][2018-05-25 16:16:56,945][com.hl95.common.controller.SmsManageController]数据提交失败！
java.sql.SQLException: Column Index out of range, 2 > 1. 
	at com.mysql.jdbc.SQLError.createSQLException(SQLError.java:996)
	at com.mysql.jdbc.SQLError.createSQLException(SQLError.java:935)
	at com.mysql.jdbc.SQLError.createSQLException(SQLError.java:924)
	at com.mysql.jdbc.SQLError.createSQLException(SQLError.java:870)
	at com.mysql.jdbc.ResultSetImpl.checkColumnBounds(ResultSetImpl.java:758)
	at com.mysql.jdbc.ResultSetImpl.getStringInternal(ResultSetImpl.java:5240)
	at com.mysql.jdbc.ResultSetImpl.getString(ResultSetImpl.java:5162)
	at com.hl95.common.controller.SmsManageController.propelSms(SmsManageController.java:120)
	at sun.reflect.NativeMethodAccessorImpl.invoke0(Native Method)
	at sun.reflect.NativeMethodAccessorImpl.invoke(NativeMethodAccessorImpl.java:62)
	at sun.reflect.DelegatingMethodAccessorImpl.invoke(DelegatingMethodAccessorImpl.java:43)
	at java.lang.reflect.Method.invoke(Method.java:498)
	at org.springframework.scheduling.support.ScheduledMethodRunnable.run(ScheduledMethodRunnable.java:65)
	at org.springframework.scheduling.support.DelegatingErrorHandlingRunnable.run(DelegatingErrorHandlingRunnable.java:54)
	at java.util.concurrent.Executors$RunnableAdapter.call(Executors.java:511)
	at java.util.concurrent.FutureTask.runAndReset(FutureTask.java:308)
	at java.util.concurrent.ScheduledThreadPoolExecutor$ScheduledFutureTask.access$301(ScheduledThreadPoolExecutor.java:180)
	at java.util.concurrent.ScheduledThreadPoolExecutor$ScheduledFutureTask.run(ScheduledThreadPoolExecutor.java:294)
	at java.util.concurrent.ThreadPoolExecutor.runWorker(ThreadPoolExecutor.java:1149)
	at java.util.concurrent.ThreadPoolExecutor$Worker.run(ThreadPoolExecutor.java:624)
	at java.lang.Thread.run(Thread.java:748)
[ERROR][2018-05-25 16:16:58,635][com.hl95.common.controller.SmsManageController]数据提交失败！
java.sql.SQLException: Column Index out of range, 2 > 1. 
	at com.mysql.jdbc.SQLError.createSQLException(SQLError.java:996)
	at com.mysql.jdbc.SQLError.createSQLException(SQLError.java:935)
	at com.mysql.jdbc.SQLError.createSQLException(SQLError.java:924)
	at com.mysql.jdbc.SQLError.createSQLException(SQLError.java:870)
	at com.mysql.jdbc.ResultSetImpl.checkColumnBounds(ResultSetImpl.java:758)
	at com.mysql.jdbc.ResultSetImpl.getStringInternal(ResultSetImpl.java:5240)
	at com.mysql.jdbc.ResultSetImpl.getString(ResultSetImpl.java:5162)
	at com.hl95.common.controller.SmsManageController.propelSms(SmsManageController.java:120)
	at sun.reflect.GeneratedMethodAccessor8.invoke(Unknown Source)
	at sun.reflect.DelegatingMethodAccessorImpl.invoke(DelegatingMethodAccessorImpl.java:43)
	at java.lang.reflect.Method.invoke(Method.java:498)
	at org.springframework.scheduling.support.ScheduledMethodRunnable.run(ScheduledMethodRunnable.java:65)
	at org.springframework.scheduling.support.DelegatingErrorHandlingRunnable.run(DelegatingErrorHandlingRunnable.java:54)
	at java.util.concurrent.Executors$RunnableAdapter.call(Executors.java:511)
	at java.util.concurrent.FutureTask.runAndReset(FutureTask.java:308)
	at java.util.concurrent.ScheduledThreadPoolExecutor$ScheduledFutureTask.access$301(ScheduledThreadPoolExecutor.java:180)
	at java.util.concurrent.ScheduledThreadPoolExecutor$ScheduledFutureTask.run(ScheduledThreadPoolExecutor.java:294)
	at java.util.concurrent.ThreadPoolExecutor.runWorker(ThreadPoolExecutor.java:1149)
	at java.util.concurrent.ThreadPoolExecutor$Worker.run(ThreadPoolExecutor.java:624)
	at java.lang.Thread.run(Thread.java:748)
